Workbook

Sheet TVRA
U1: STUDENT NAMES: AYAAN, CHINAZO, SHIZA AND THURUVAN
A3: ADVERSARIAL RISK | AF3: Non-Adversarial Risk
A4: Threat Events | B4: Threat Source | C4: Vulnerability ID | D4: Security Controls | E4: Capabilites | F4: Intent | G4: Targeting | H4: Relevancy | I4: Likelihood of Events Occuring | J4: Vulnerabilites and Predisposing Conditions | K4: Severity | L4: Likelihood of Success | M4: Overall Likelihood | N4: Level of Impact | O4: Risk | P4: Control Effectiveness | Q4: Residual Risk | AF4: Threat Events | AG4: Threat Source | AH4: Vulnerabilitiy ID | AI4: Security Controls | AJ4: Range of Effects | AK4: Relevancy | AL4: Likelihood of Events Occuring | AM4: Vulnerabilites and Predisposing Conditions | AN4: Severity | AO4: Likelihood of Impact | AP4: Overall Likelihoood | AQ4: Level of Impact | AR4: Risk | AS4: Control Effectiveness | AT4: Residual Risk
A5: Perform perimeter network reconnaissance/scanning. | B5: Outsider | C5: VID-001 | D5: SC-7,SI-4,AC-3 | E5: High | F5: High | G5: High | H5: Possible | I5: High | J5: High | K5: High | L5: High | M5: {=INDEX('G234'!$A$24:$A$28, MATCH(TRUE, ROUND(AVERAGE( VLOOKUP(E5, 'D3456'!$A$23:$C$27, 3, FALSE), VLOOKUP(F5, 'D3456'!$A$32:$C$36, 3, FALSE), VLOOKUP(G5, 'D3456'!$A$4:$C$8, 3, FALSE) ) / 2, 0) >= ('G234'!$C$24:$C$28) / 2, 0))} -> High | N5: High | O5: =INDEX($V$16:$Z$20,MATCH(Table4335[[#This Row],[Overall Likelihood]],$U$16:$U$20,0),MATCH(Table4335[[#This Row],[Level of Impact]],$V$15:$Z$15,0)) -> High | P5: Moderate | Q5: =INDEX('Control Effectiveness Assessmen'!$A$13:$A$17, MATCH( ROUND(VLOOKUP(O5, 'Control Effectiveness Assessmen'!$A$13:$B$17, 2, FALSE) * (1 - (VLOOKUP(P5, 'Control Effectiveness Assessmen'!$A$13:$B$17, 2, FALSE) / 10)), 0), 'Control Effectiveness Assessmen'!$B$13:$B$17, 0)) -> Moderate | AF5: Disk error | AG5: OS | AH5: VID-005 | AI5: CP-10, SC-22, SC-24 | AJ5: High | AK5: Possible | AL5: High | AM5: Moderate | AN5: Moderate | AO5: High | AP5: {=INDEX('G234'!$A$24:$A$28, MATCH(TRUE, VLOOKUP(AJ5, 'D3456'!$A$14:$C$18, 3, FALSE) >= 'G234'!$C$24:$C$28, 0))} -> High | AQ5: High | AR5: =INDEX($V$16:$Z$20,MATCH(Table37[[#This Row],[Overall Likelihoood]],$U$16:$U$20,0),MATCH(Table37[[#This Row],[Level of Impact]],$V$15:$Z$15,0)) -> High | AS5: Moderate | AT5: =INDEX('Control Effectiveness Assessmen'!$A$13:$A$17, MATCH( ROUND(VLOOKUP(AR5, 'Control Effectiveness Assessmen'!$A$13:$B$17, 2, FALSE) * (1 - (VLOOKUP(AS5, 'Control Effectiveness Assessmen'!$A$13:$B$17, 2, FALSE) / 10)), 0), 'Control Effectiveness Assessmen'!$B$13:$B$17, 0)) -> Moderate
A6: Exploit poorly configured or unauthorized information systems exposed to the Internet. | B6: Outsider | C6: VID-002 | D6: AC-3,AC-4,SC-7 | E6: High | F6: High | G6: High | H6: Possible | I6: High | J6: High | K6: High | L6: High | M6: {=INDEX('G234'!$A$24:$A$28, MATCH(TRUE, ROUND(AVERAGE( VLOOKUP(E6, 'D3456'!$A$23:$C$27, 3, FALSE), VLOOKUP(F6, 'D3456'!$A$32:$C$36, 3, FALSE), VLOOKUP(G6, 'D3456'!$A$4:$C$8, 3, FALSE) ) / 2, 0) >= ('G234'!$C$24:$C$28) / 2, 0))} -> High | N6: Very High | O6: =INDEX($V$16:$Z$20,MATCH(Table4335[[#This Row],[Overall Likelihood]],$U$16:$U$20,0),MATCH(Table4335[[#This Row],[Level of Impact]],$V$15:$Z$15,0)) -> Very High | P6: Moderate | Q6: =INDEX('Control Effectiveness Assessmen'!$A$13:$A$17, MATCH( ROUND(VLOOKUP(O6, 'Control Effectiveness Assessmen'!$A$13:$B$17, 2, FALSE) * (1 - (VLOOKUP(P6, 'Control Effectiveness Assessmen'!$A$13:$B$17, 2, FALSE) / 10)), 0), 'Control Effectiveness Assessmen'!$B$13:$B$17, 0)) -> High
A7: Conduct externally-based network traffic modification (man in the middle) attacks. | B7: Outsider | C7: VID-003 | D7: SC-12,SC-13,AC-3 | E7: High | F7: High | G7: High | H7: Possible | I7: High | J7: High | K7: High | L7: High | M7: {=INDEX('G234'!$A$24:$A$28, MATCH(TRUE, ROUND(AVERAGE( VLOOKUP(E7, 'D3456'!$A$23:$C$27, 3, FALSE), VLOOKUP(F7, 'D3456'!$A$32:$C$36, 3, FALSE), VLOOKUP(G7, 'D3456'!$A$4:$C$8, 3, FALSE) ) / 2, 0) >= ('G234'!$C$24:$C$28) / 2, 0))} -> High | N7: High | O7: =INDEX($V$16:$Z$20,MATCH(Table4335[[#This Row],[Overall Likelihood]],$U$16:$U$20,0),MATCH(Table4335[[#This Row],[Level of Impact]],$V$15:$Z$15,0)) -> High | P7: Moderate | Q7: =INDEX('Control Effectiveness Assessmen'!$A$13:$A$17, MATCH( ROUND(VLOOKUP(O7, 'Control Effectiveness Assessmen'!$A$13:$B$17, 2, FALSE) * (1 - (VLOOKUP(P7, 'Control Effectiveness Assessmen'!$A$13:$B$17, 2, FALSE) / 10)), 0), 'Control Effectiveness Assessmen'!$B$13:$B$17, 0)) -> Moderate
A8: Exploit poorly configured or unauthorized information systems exposed to the Internet. | B8: Outsider | C8: VID-004 | D8: SC-7,AC-4,CM-7,RA-5,SI-4 | E8: High | F8: High | G8: High | H8: Possible | I8: High | J8: High | K8: High | L8: High | M8: {=INDEX('G234'!$A$24:$A$28, MATCH(TRUE, ROUND(AVERAGE( VLOOKUP(E8, 'D3456'!$A$23:$C$27, 3, FALSE), VLOOKUP(F8, 'D3456'!$A$32:$C$36, 3, FALSE), VLOOKUP(G8, 'D3456'!$A$4:$C$8, 3, FALSE) ) / 2, 0) >= ('G234'!$C$24:$C$28) / 2, 0))} -> High | N8: High | O8: =INDEX($V$16:$Z$20,MATCH(Table4335[[#This Row],[Overall Likelihood]],$U$16:$U$20,0),MATCH(Table4335[[#This Row],[Level of Impact]],$V$15:$Z$15,0)) -> High | P8: Moderate | Q8: =INDEX('Control Effectiveness Assessmen'!$A$13:$A$17, MATCH( ROUND(VLOOKUP(O8, 'Control Effectiveness Assessmen'!$A$13:$B$17, 2, FALSE) * (1 - (VLOOKUP(P8, 'Control Effectiveness Assessmen'!$A$13:$B$17, 2, FALSE) / 10)), 0), 'Control Effectiveness Assessmen'!$B$13:$B$17, 0)) -> Moderate
A9: Exploit recently discovered vulnerabilities. | B9: Outsider | C9: VID-006 | D9: AC-6, IA-2, SC-12, SC-13 | E9: High | F9: High | G9: High | H9: Possible | I9: High | J9: High | K9: High | L9: High | M9: {=INDEX('G234'!$A$24:$A$28, MATCH(TRUE, ROUND(AVERAGE( VLOOKUP(E9, 'D3456'!$A$23:$C$27, 3, FALSE), VLOOKUP(F9, 'D3456'!$A$32:$C$36, 3, FALSE), VLOOKUP(G9, 'D3456'!$A$4:$C$8, 3, FALSE) ) / 2, 0) >= ('G234'!$C$24:$C$28) / 2, 0))} -> High | N9: High | O9: =INDEX($V$16:$Z$20,MATCH(Table4335[[#This Row],[Overall Likelihood]],$U$16:$U$20,0),MATCH(Table4335[[#This Row],[Level of Impact]],$V$15:$Z$15,0)) -> High | P9: Moderate | Q9: =INDEX('Control Effectiveness Assessmen'!$A$13:$A$17, MATCH( ROUND(VLOOKUP(O9, 'Control Effectiveness Assessmen'!$A$13:$B$17, 2, FALSE) * (1 - (VLOOKUP(P9, 'Control Effectiveness Assessmen'!$A$13:$B$17, 2, FALSE) / 10)), 0), 'Control Effectiveness Assessmen'!$B$13:$B$17, 0)) -> Moderate
A10: Exploit poorly configured or unauthorized information systems exposed to the Internet. | B10: Outsider | C10: VID-007 | D10: SC-7,SC-12,SC-13 | E10: Moderate | F10: High | G10: Moderate | H10: Possible | I10: Moderate | J10: Moderate | K10: Moderate | L10: High | M10: {=INDEX('G234'!$A$24:$A$28, MATCH(TRUE, ROUND(AVERAGE( VLOOKUP(E10, 'D3456'!$A$23:$C$27, 3, FALSE), VLOOKUP(F10, 'D3456'!$A$32:$C$36, 3, FALSE), VLOOKUP(G10, 'D3456'!$A$4:$C$8, 3, FALSE) ) / 2, 0) >= ('G234'!$C$24:$C$28) / 2, 0))} -> Moderate | N10: High | O10: =INDEX($V$16:$Z$20,MATCH(Table4335[[#This Row],[Overall Likelihood]],$U$16:$U$20,0),MATCH(Table4335[[#This Row],[Level of Impact]],$V$15:$Z$15,0)) -> High | P10: Moderate | Q10: =INDEX('Control Effectiveness Assessmen'!$A$13:$A$17, MATCH( ROUND(VLOOKUP(O10, 'Control Effectiveness Assessmen'!$A$13:$B$17, 2, FALSE) * (1 - (VLOOKUP(P10, 'Control Effectiveness Assessmen'!$A$13:$B$17, 2, FALSE) / 10)), 0), 'Control Effectiveness Assessmen'!$B$13:$B$17, 0)) -> Moderate | U10: RISK MATRIX
A11: Obtain sensitive information via exfiltration. | B11: Outsider | C11: VID-008 | D11: SC-7-SC-21,AC-4 | E11: High | F11: High | G11: High | H11: Possible | I11: Moderate | J11: Moderate | K11: High | L11: Moderate | M11: {=INDEX('G234'!$A$24:$A$28, MATCH(TRUE, ROUND(AVERAGE( VLOOKUP(E11, 'D3456'!$A$23:$C$27, 3, FALSE), VLOOKUP(F11, 'D3456'!$A$32:$C$36, 3, FALSE), VLOOKUP(G11, 'D3456'!$A$4:$C$8, 3, FALSE) ) / 2, 0) >= ('G234'!$C$24:$C$28) / 2, 0))} -> High | N11: High | O11: =INDEX($V$16:$Z$20,MATCH(Table4335[[#This Row],[Overall Likelihood]],$U$16:$U$20,0),MATCH(Table4335[[#This Row],[Level of Impact]],$V$15:$Z$15,0)) -> High | P11: Moderate | Q11: =INDEX('Control Effectiveness Assessmen'!$A$13:$A$17, MATCH( ROUND(VLOOKUP(O11, 'Control Effectiveness Assessmen'!$A$13:$B$17, 2, FALSE) * (1 - (VLOOKUP(P11, 'Control Effectiveness Assessmen'!$A$13:$B$17, 2, FALSE) / 10)), 0), 'Control Effectiveness Assessmen'!$B$13:$B$17, 0)) -> Moderate
A12: Conduct simple Denial of Service (DoS) attack. | B12: Outsider | C12: VID-009 | D12: SC-5,SC-7,SC-6,SI-4 | E12: High | F12: High | G12: Moderate | H12: Possible | I12: High | J12: Moderate | K12: Moderate | L12: High | M12: {=INDEX('G234'!$A$24:$A$28, MATCH(TRUE, ROUND(AVERAGE( VLOOKUP(E12, 'D3456'!$A$23:$C$27, 3, FALSE), VLOOKUP(F12, 'D3456'!$A$32:$C$36, 3, FALSE), VLOOKUP(G12, 'D3456'!$A$4:$C$8, 3, FALSE) ) / 2, 0) >= ('G234'!$C$24:$C$28) / 2, 0))} -> High | N12: High | O12: =INDEX($V$16:$Z$20,MATCH(Table4335[[#This Row],[Overall Likelihood]],$U$16:$U$20,0),MATCH(Table4335[[#This Row],[Level of Impact]],$V$15:$Z$15,0)) -> High | P12: Moderate | Q12: =INDEX('Control Effectiveness Assessmen'!$A$13:$A$17, MATCH( ROUND(VLOOKUP(O12, 'Control Effectiveness Assessmen'!$A$13:$B$17, 2, FALSE) * (1 - (VLOOKUP(P12, 'Control Effectiveness Assessmen'!$A$13:$B$17, 2, FALSE) / 10)), 0), 'Control Effectiveness Assessmen'!$B$13:$B$17, 0)) -> Moderate
A13: Cause integrity loss by creating, deleting, and/or modifying data on publicly accessible information systems (e.g., web defacement). | B13: Outsider | C13: VID-010 | D13: SC-18,SC-19,SC-20,SC-21 | E13: Moderate | F13: High | G13: Moderate | H13: Possible | I13: Moderate | J13: Moderate | K13: Moderate | L13: High | M13: {=INDEX('G234'!$A$24:$A$28, MATCH(TRUE, ROUND(AVERAGE( VLOOKUP(E13, 'D3456'!$A$23:$C$27, 3, FALSE), VLOOKUP(F13, 'D3456'!$A$32:$C$36, 3, FALSE), VLOOKUP(G13, 'D3456'!$A$4:$C$8, 3, FALSE) ) / 2, 0) >= ('G234'!$C$24:$C$28) / 2, 0))} -> Moderate | N13: High | O13: =INDEX($V$16:$Z$20,MATCH(Table4335[[#This Row],[Overall Likelihood]],$U$16:$U$20,0),MATCH(Table4335[[#This Row],[Level of Impact]],$V$15:$Z$15,0)) -> High | P13: Moderate | Q13: =INDEX('Control Effectiveness Assessmen'!$A$13:$A$17, MATCH( ROUND(VLOOKUP(O13, 'Control Effectiveness Assessmen'!$A$13:$B$17, 2, FALSE) * (1 - (VLOOKUP(P13, 'Control Effectiveness Assessmen'!$A$13:$B$17, 2, FALSE) / 10)), 0), 'Control Effectiveness Assessmen'!$B$13:$B$17, 0)) -> Moderate
V14: Level of Impact
U15: Overall Likelihood | V15: Very Low | W15: Low | X15: Moderate | Y15: High | Z15: Very High
U16: Very High | V16: Low | W16: Moderate | X16: High | Y16: Very High | Z16: Very High
U17: High | V17: Low | W17: Moderate | X17: High | Y17: High | Z17: Very High
U18: Moderate | V18: Low | W18: Moderate | X18: Moderate | Y18: High | Z18: High
U19: Low | V19: Low | W19: Low | X19: Moderate | Y19: Moderate | Z19: High
U20: Very Low | V20: Very Low | W20: Low | X20: Low | Y20: Moderate | Z20: Moderate

Sheet Vulnerabilities Catalog
A1: ID | B1: Name | C1: CVE | D1: Description | E1: Category | F1: Discovery | G1: Discovery Date | H1: Affected Versions | I1: Attack Vector | J1: Impact Type
A2: ID-001 | B2: Zone Transfer Allowed (DNS Discovery) | C2: N/A | D2: DNS servers allow unauthorized zone transfers, exposing hostnames and IPs. Adversaries can perform reconnaissance to map the network and plan attacks. | E2: Adversarial | F2: Outsider | G2: 45915 | H2: DNS servers (corpweb.g5.local) | I2: Network (External) | J2: Confidentiality, Integrity, Availability
A3: VID-002 | B3: Misconfigured Internet-Facing Systems | C3: N/A | D3: Unauthorized or misconfigured systems are exposed to the Internet, allowing attackers to exploit them for access or pivoting. | E3: Adversarial | F3: Outsider | G3: 45915 | H3: Externally exposed servers, proxies | I3: Network (External) | J3: Confidentiality, Integrity, Availability
A4: VID-003 | B4: Proxy Without TLS (Unencrypted Traffic) | C4: N/A | D4: Proxy allows plain HTTP connections. Adversaries can sniff or modify traffic, steal logins, and hijack sessions. | E4: Adversarial | F4: Outsider | G4: 45915 | H4: Reverse proxy, web applications | I4: Network (External) | J4: Confidentiality, Integrity, Availability
A5: VID-004 | B5: Insecure Internal Services | C5: N/A | D5: Internal services (SSH) are exposed or misconfigured, enabling lateral movement and privilege escalation. | E5: Adversarial | F5: Outsider | G5: 45915 | H5: Internal servers | I5: Network (Internal) | J5: Confidentiality, Integrity, Availability
A6: VID-005 | B6: Single Point of Failure in AD/DNS | C6: N/A | D6: Active Directory also runs DNS. If the AD VM fails, both authentication and DNS resolution will stop. This disrupts logins and makes services unreachable via FQDN | E6: Non-Adversial | F6: System | G6: 45915 | H6: Unpatched servers, apps | I6: Network (External/Internal) | J6: Confidentiality, Integrity, Availability
A7: VID-006 | B7: Active Directory Security Weakness | C7: N/A | D7: Without LDAPS, credentials travel in plaintext, allowing attackers to sniff traffic and steal hashes. | E7: Adversarial | F7: Outsider | G7: 45915 | H7: AD VM, DNS | I7: Local/System Dependency | J7: Confidentiality, Integrity, Availability
A8: VID-007 | B8: Partial Service Exposure (Backends on Port 80) | C8: N/A | D8: Backend services run on port 80 behind the proxy. If the proxy misroutes traffic, attackers could reach backends directly in clear-text. | E8: Adversarial | F8: Outsider | G8: 45915 | H8: AD, LDAP Kerberos | I8: Network (Internal) | J8: Confidentiality, Integrity, Availability
A9: VID-008 | B9: Data Exfiltration (No Container Egress Limits) | C9: N/A | D9: Containers can make unrestricted outbound connections. If compromised, they could exfiltrate data or connect to attacker servers. | E9: Adversarial | F9: Outsider | G9: 45915 | H9: Containerized applications | I9: Network (Internal/External) | J9: Confidentiality, Integrity, Availability
A10: VID-009 | B10: Denial of Service (DoS) | C10: N/A | D10: External services can be overwhelmed with traffic, making them unavailable or slow for legitimate users. | E10: Adversarial | F10: Outsider | G10: 45915 | H10: Reverse proxy, DNS, web servers | I10: Network (External) | J10: Availability (Primary), Confidentiality/Integrity (Secondary)
A11: VID-010 | B11: Web Defacement (Missing Security Headers) | C11: N/A | D11: Public-facing web apps lack basic headers (CSP, X-Frame, HSTS). This allows attacks like clickjacking, XSS, or defacement that impact site integrity and user trust. | E11: Adversarial | F11: Outsider | G11: 45915 | H11: Public web servers | I11: Web/Application Layer | J11: Integrity, Availability

Sheet Threat Source Catalog
A1: Threat Source Catalog
A2: ID | B2: Source Type | C2: Description | D2: Characteristics | E2: Associated Vulns
A3: TS1 | B3: Adversarial | C3: DNS reconnaissance and weak external services | D3: Poor DNS hardening (zone transfers) and exposed services give attackers mapping and intrusion vectors | E3: VID-001, VID-002
A4: TS2 | B4: Adversarial | C4: Weak encryption and insecure proxy configs | D4: Unencrypted HTTP traffic can be sniffed or hijacked; proxy flaws expose backend systems | E4: VID-003, VID-007
A5: TS3 | B5: Adversarial | C5: Exploiting weak/misconfigured internal services | D5: Attackers leverage exposed SSH or backend flaws for lateral movement and privilege escalation | E5: VID-004, VID-006
A6: TS4 | B6: Non-Adversarial | C6: Service dependency / infrastructure single points of failure | D6: Failures in AD/DNS create cascading outages that disrupt authentication and resolution | E6: VID-005
A7: TS5 | B7: Adversarial | C7: Data exfiltration via container misuse | D7: Lack of outbound filtering allows compromised containers to beacon or exfiltrate sensitive data | E7: VID-008
A8: TS6 | B8: Adversarial | C8: Disruption of service availability | D8: Adversaries flood services to cause outages or degrade performance (DoS) | E8: VID-009
A9: TS7 | B9: Adversarial | C9: Exploitation of weak web security controls | D9: Missing headers allow defacement, clickjacking, or XSS that undermines site integrity | E9: VID-010

Sheet Security Controls Catalog
A1: Control ID | B1: Control Name
A2: AC-16 | B2: Security Attributes
A3: AC-19 | B3: Access controls for Mobile Devices
A4: AC-2 | B4: Account Management
A5: AU-12 | B5: Audit Record Generation
A6: CM-2 | B6: Baseline Configuration
A7: CP-9 | B7: Information System Backup
A8: IA-2 | B8: Identification & Authentication
A9: IR-4 | B9: Incident Handling
A10: IR-5 | B10: Incident Monitoring
A11: PE-3 | B11: Physical Access Control
A12: SC-12 | B12: Cryptographic Key establishment and Manegement
... A201: SC-39 | B201: Process Isolation

Sheet Threat Events Catalog
A1: TABLE E-5: TEMPLATE – IDENTIFICATION OF THREAT EVENTS
A2: Identifier | B2: Threat Event Source of Information | C2: Threat Source | D2: Relevance
A3: Organization -defined | B3: Table E-2, Table E-3, Task 1-4 or Organization-defined | C3: Table D-7, Table D-8 or Organization-defined | D3: Table E-4 or Organizationdefined
A4: 1 | B4: Incorrect privilege settings | C4: Privileged Insider | D4: Confirmed
A5: 2 | B5: Unreadable display | C5: Display | D5: N/A
A6: 3 | B6: Disk error | C6: Storage | D6: Possible
A7: 4 | B7: Exploit vulnerabilities on internal organizational information systems. | C7: Outsider | D7: Confirmed
A8: 5 | B8: Fire at backup facility | C8: Established | D8: Anticipated
A9: 6 | B9: Obtain unauthorized access. | C9: Natural or man made disaster | D9: Confirmed
A10: 7 | B10: Conduct attacks targeting and compromising personal devices of critical employees. | C10: Outsider | D10: Confirmed
A11: 8 | B11: Cause unauthorized disclosure and/or unavailability by spilling sensitive information. | C11: Outsider | D11: Confirmed
A12: 9 | B12: Conduct physical attacks on infrastructures supporting organizational facilities. | C12: Trusted Insider | D12: Possible
A13: 10 | B13: Spill sensitive information | C13: Overrun | D13: Confirmed
A14: 11 | B14: Mishandling of critical and/or sensitive information by authorized users | C14: Trusted Insider | D14: Confirmed
A15: 12 | B15: Communications contention | C15: Communications | D15: Possible
... A112: 109 | B112: Coordinate cyber attacks using external (outsider), internal (insider), and supply chain (supplier) attack vectors. | C112: Outsider | D112: Confirmed
D113: N/A
A115: TABLE E-2 REPRESENTATIVE EXAMPLES - ADVERSIAL THREAT EVENTS
A116: Threat Events | B116: Description
A117: Adapt cyber attacks based on detailed surveillance. | B117: Adversary adapts behavior in response to surveillance and organizational security measures.
A118: Cause degradation or denial of attacker-selected services or capabilities. | B118: Adversary directs malware on organizational systems to impair the correct and timely support of organizational mission/business functions.
A119: Cause deterioration/destruction of critical information system components and functions. | B119: Adversary destroys or causes deterioration of critical information system components to impede or eliminate organizational ability to carry out missions or business functions. Detection of this action is not a concern.
A120: Cause disclosure of critical and/or sensitive information by authorized users. | B120: Adversary induces (e.g., via social engineering) authorized users to inadvertently expose, disclose, or mishandle critical/sensitive information.
A121: Cause integrity loss by creating, deleting, and/or modifying data on publicly accessible information systems (e.g., web defacement). | B121: Adversary vandalizes, or otherwise makes unauthorized changes to, organizational websites or data on websites.
A122: Cause integrity loss by injecting false but believable data into organizational information systems. | B122: Adversary injects false but believable data into organizational information systems, resulting in suboptimal actions or loss of confidence in organizational data/services.
A123: Cause integrity loss by polluting or corrupting critical data. | B123: Adversary implants corrupted and incorrect data in critical data, resulting in suboptimal actions or loss of confidence in organizational data/services.
A124: Cause unauthorized disclosure and/or unavailability by spilling sensitive information. | B124: Adversary contaminates organizational information systems (including devices and networks) by causing them to handle information of a classification/sensitivity for which they have not been authorized. The information is exposed to individuals who are not authorized access to such information, and the information system, device, or network is unavailable while the spill is investigated and mitigated.
A125: Compromise critical information systems via physical access. | B125: Adversary obtains physical access to organizational information systems and makes modifications.
A126: Compromise design, manufacture, and/or distribution of information system components (including hardware, software, and firmware). | B126: Adversary compromises the design, manufacture, and/or distribution of critical information system components at selected suppliers.
A127: Compromise information systems or devices used externally and reintroduced into the enterprise. | B127: Adversary installs malware on information systems or devices while the
... A201: Redirect victims to malicious websites via HTML injection | B201: An attacker exploits the HTML injection vulnerability in Zoom's display name field to embed malicious links. When victims interact with these links, they are redirected to malicious websites, potentially exposing them to phishing attacks or malware.
B202: missions/business functions. Adversary may target privileged functions to gain access to sensitive information (e.g., user accounts, system files, etc.) and may leverage access to one privileged capability to get to another capability.
A203: Exploit local privilege escalation to delete critical files | B203: An attacker exploits a local privilege escalation vulnerability in Zoom's installer repair process to gain elevated privileges. This allows them to delete critical system-level files or folders, potentially compromising the system's integrity and availability, leading to crashes or service disruptions.
A204: Exploit local privilege escalation via installer scripts | B204: This threat involves leveraging improperly secured installer scripts to execute arbitrary commands with elevated privileges. An attacker with local access can exploit writable directories or misconfigured scripts during the installation process to gain higher-level access, potentially compromising system integrity and security.
B205: A malicious actor uses improperly verified installer files to deliver unauthorized software, leveraging .msi, .ps1, and .bat extensions. The attack impacts system integrity by introducing malicious components into the installation process, potentially leading to further exploitation or system compromise.
A206: Exploit path traversal to execute unintended files
B207: An attacker exploits a STUN parsing vulnerability by sending malformed UDP packets to Zoom clients, causing the application to crash and resulting in a denial-of-service condition.
B208: systems/devices are external to organizations for purposes of subsequently infecting organizations when reconnected.
B209: organizations (or organizational personnel) use to transmit information (e.g., kiosks, public wireless networks) intercepts communications.
A211: TABLE E-3: REPRESENTATIVE EXAMPLES - NON-ADVERSARIAL THREAT EVENTS
...

Sheet D78
A1: TABLE D-7 TEMPLATE - IDENTIFICANTION OF ADVERSARIAL THREAT SOURCES
A2: Identifer | B2: Threat Source | C2: In Scope | D2: Capabilities | E2: Intent | F2: Targeting
A3: Organization-defined | B3: TABLE D-2 and Task 1-4 or Organization-defined | C3: YES/NO | D3: Table D-3 | E3: Table D-4 | F3: Table D-5
A4: 1 | B4: Ad hoc | C4: No | D4: Low | E4: Low | F4: Low
A5: 2 | B5: Competitor | C5: Yes | D5: Moderate | E5: High | F5: High
A6: 3 | B6: Customer | C6: No | D6: Low | E6: Low | F6: Low
A7: 4 | B7: Established | C7: Yes | D7: Moderate | E7: Moderate | F7: Moderate
A8: 5 | B8: Group | C8: Yes | D8: High | E8: Moderate | F8: Moderate
A9: 6 | B9: Nation-State | C9: Yes | D9: Very High | E9: Very High | F9: Very High
A10: 7 | B10: Organization | C10: Yes | D10: High | E10: High | F10: High
A11: 8 | B11: Outsider | C11: Yes | D11: Moderate | E11: High | F11: Moderate
A12: 9 | B12: Partner | C12: Yes | D12: Moderate | E12: Low | F12: Moderate
A13: 10 | B13: Privileged Insider | C13: Yes | D13: Very High | E13: High | F13: Very High
A14: 11 | B14: Supplier | C14: Yes | D14: Moderate | E14: Moderate | F14: Moderate
A15: 12 | B15: Trusted Insider | C15: Yes | D15: Very High | E15: Very High | F15: Very High
A19: TABLE D-8 - IDENTIFICATION OF NON-ADVERSARIAL THREAT SOURCES | F19: Threat Sources full List
A20: Identifer | B20: Threat Source | C20: In Scope | D20: Range of Effects | F20: Ad hoc
A21: 1 | B21: User | C21: Yes | D21: High | F21: Bombing
A22: 2 | B22: Privileged User | C22: Yes | D22: Very High | F22: Communications
A23: 3 | B23: Storage | C23: Yes | D23: High | F23: Competitor
A24: 4 | B24: Processing | C24: Yes | D24: High | F24: Controller
A25: 5 | B25: Communications | C25: Yes | D25: Very High | F25: Customer
A26: 6 | B26: Display | C26: No | D26: Low | F26: Display
A27: 7 | B27: Sensor | C27: Yes | D27: Moderate | F27: Earthquake
A28: 8 | B28: Controller | C28: Yes | D28: Very High | F28: Electrical Power
A29: 9 | B29: Temperature/Humidity Control | C29: No | D29: Low | F29: Environmental Controls
A30: 10 | B30: Power Supply | C30: Yes | D30: Very High | F30: Established
A31: 11 | B31: OS | C31: Yes | D31: Very High | F31: fire
A32: 12 | B32: Networking | C32: Yes | D32: Very High | F32: Flood/Tsunami
... A48: 28 | B48: Environmental Controls | C48: No | D48: Low | F48: Privileged User
F49: Processing
F50: Sensor
F51: Software
F52: Storage
F53: Supplier
F54: Telecommunications
F55: Temperature/Humidity Control
F56: Trusted Insider
F57: Unusual Natural Event
F58: User
...

Sheet D3456
A1: TABLE D-5: ASSESSMENT SCALE - CHARACTERISTIC OF ADVERSARY TARGETING
A3: Qualitative Values | B3: Semi Quantitative Values | C3: Semi Quantitative Values | D3: Description
A4: Very High | B4: 96 to 100 | C4: 10 | D4: The adversary analyzes information obtained via reconnaissance and attacks to target persistently a specific organization, enterprise, program, mission or business function, focusing on specific high-value or mission-critical information, resources, supply flows, or functions; specific employees or positions; supporting infrastructure providers/suppliers; or partnering organizations
A5: High | B5: 80 to 95 | C5: 8 | D5: The adversary analyzes information obtained via reconnaissance to target persistently a specific organization, enterprise, program, mission or business function, focusing on specific high-value or mission-critical information , resources, supply flows, or functions, specific employees supporting those functions, or key positions.
A6: Moderate | B6: 21 to 79 | C6: 5 | D6: The adversary analyzes publicly available information to target persistently specific high-value organizations (and key positions, such as Chief Information Officer), programs, or information.
A7: Low | B7: 5 to 20 | C7: 2 | D7: The adversary uses publicly available information to target a class of high-value organizations or information, and seeks targets of opportunity within that class
A8: Very Low | B8: 0 to 4 | C8: 0 | D8: The adversary may or may not target any specific organizations or classes of organizations
A11: TABLE D-6: ASSESMENT SCALE - E – RANGE OF EFFECTS FOR NON-ADVERSARIAL THREAT SOURCES
A13: Qulitative Value | B13: Semi- Quantitative Value | C13: Semi-Quantitave Values | D13: Description
A14: Very High | B14: 96-100 | C14: 10 | D14: The effects of the error, accident, or act of nature are sweeping, involving almost all of the cyber resources of the [Tier 3: information systems; Tier 2: mission/business processes or EA segments, common infrastructure, or support services; Tier 1: organization/governance structure].
A15: High | B15: 80 to 95 | C15: 8 | D15: The effects of the error, accident, or act of nature are extensive, involving most of the cyber resources of the [Tier 3: information systems; Tier 2: mission/business processes or EA segments, common infrastructure, or support services; Tier 1: organization/governance structure], including many critical resources.
A16: Moderate | B16: 21 to 79 | C16: 5 | D16: The effects of the error, accident, or act of nature are wide-ranging, involving a significant portion of the cyber resources of the [Tier 3: information systems; Tier 2: mission/business processes or EA segments, common infrastructure, or support services; Tier 1: organization/governance structure], including some critical resources.
A17: Low | B17: 5 to 20 | C17: 2 | D17: The effects of the error, accident, or act of nature are limited, involving some of the cyber resources of the [Tier 3: information systems; Tier 2: mission/business processes or EA segments, common infrastructure, or support services; Tier 1: organization/governance structure], but involving no critical resources.
A18: Very Low | B18: 0 to 4 | C18: 0 | D18: The effects of the error, accident, or act of nature are minimal, involving few if any of the cyber resources of the [Tier 3: information systems; Tier 2: mission/business processes or EA segments, common infrastructure, or support services; Tier 1: organization/governance structure], and involving no critical resources.
A20: TABLE D-3: ASSESMENT SCALE - CHARACTERISTICS OF ADVERSARY CAPABILITY
A22: Qulitative Value | B22: Semi- Quantitative Value | C22: Semi-Quantitave Values | D22: Description
A23: Very High | B23: 96-100 | C23: 10 | D23: The adversary has a very sophisticated level of expertise, is well-resourced, and can generate opportunities to support multiple successful, continuous, and coordinated attacks.
A24: High | B24: 80 to 95 | C24: 8 | D24: The adversary has a sophisticated level of expertise, with significant resources and opportunities to support multiple successful coordinated attacks.
A25: Moderate | B25: 21 to 79 | C25: 5 | D25: The adversary has moderate resources, expertise, and opportunities to support multiple successful attacks.
A26: Low | B26: 5 to 20 | C26: 2 | D26: The adversary has limited resources, expertise, and opportunities to support a successful attack.
A27: Very Low | B27: 0 to 4 | C27: 0 | D27: The adversary has very limited resources, expertise, and opportunities to support a successful attack.
A29: TABLE D-4: ASSESMENT SCALE - CHARACTERISTICS OF ADVERSARY INTENT
A31: Qualitative Values | B31: Semi- Quantitative Values | C31: Values | D31: Description
A32: Very High | B32: 96 to 100 | C32: 10 | D32: The adversary seeks to undermine, severely impede, or destroy a core mission or business function, program, or enterprise by exploiting a presence in the organization’s information systems or infrastructure. The adversary is concerned about disclosure of tradecraft only to the extent that it would impede its ability to complete stated goals
A33: High | B33: 80 to 95 | C33: 8 | D33: The adversary seeks to undermine/impede critical aspects of a core mission or business function, program, or enterprise, or place itself in a position to do so in the future, by maintaining a presence in the organization’s information systems or infrastructure. The adversary is very concerned about minimizing attack detection/disclosure of tradecraft, particularly while preparing for future attacks.
A34: Moderate | B34: 21 to 79 | C34: 5 | D34: The adversary seeks to obtain or modify specific critical or sensitive information or usurp/disrupt the organization’s cyber resources by establishing a foothold in the organization’s information systems or infrastructure. The adversary is concerned about minimizing attack detection/disclosure of tradecraft, particularly when carrying out attacks over long time periods. The adversary is willing to impede aspects of the organization’s missions/business functions to achieve these ends.
A35: Low | B35: 5 to 20 | C35: 2 | D35: The adversary actively seeks to obtain critical or sensitive information or to usurp/disrupt the organization’s cyber resources, and does so without concern about attack detection/disclosure of tradecraft.
A36: Very Low | B36: 0 to 4 | C36: 0 | D36: The adversary seeks to usurp, disrupt, or deface the organization’s cyber resources, and does so without concern about attack detection/disclosure of tradecraft.

Sheet Control Effectiveness Assessmen
A1: TABLE D-4: ASSESMENT SCALE - CHARACTERISTICS OF ADVERSARY INTENT
A3: Qualitative Values | B3: Semi- Quantitative Values | C3: Values | D3: Description
A4: Very High | B4: 96 to 100 | C4: 10 | D4: The control is highly effective, fully implemented, and mitigates the risk comprehensively, leaving negligible residual risk.
A5: High | B5: 80 to 95 | C5: 8 | D5: The control is effective, well-implemented, and addresses most risk scenarios, with only minor gaps or residual risks remaining.
A6: Moderate | B6: 21 to 79 | C6: 5 | D6: The control is partially effective, mitigating some risks but leaving significant gaps in coverage or inconsistent implementation, resulting in moderate residual risk.
A7: Low | B7: 5 to 20 | C7: 2 | D7: The control is minimally effective, covering only a small portion of the risk scenarios, with major gaps in coverage or poor implementation, leaving high residual risk.
A8: Very Low | B8: 0 to 4 | C8: 0 | D8: The control is ineffective, not implemented, or completely absent, leaving the risk unmitigated and fully exposed.
A10: Assessment Table
A12: Qualitative Values | B12: Values
A13: Very High | B13: 5
A14: High | B14: 4
A15: Moderate | B15: 3
A16: Low | B16: 2
A17: Very Low | B17: 1

Sheet F256
A1: TABLE F-5: ASSESSMENT SCALE – PERVASIVENESS OF PREDISPOSING CONDITIONS
A2: Qualitative Values | B2: Semi-Quantitative Values | C2: Column1 | D2: Description
A3: Very High | B3: 96-100 | C3: 10 | D3: Applies to all organizational missions/business functions (Tier 1), mission/business processes (Tier 2), or information systems (Tier 3).
A4: High | B4: 80-95 | C4: 8 | D4: Applies to most organizational missions/business functions (Tier 1), mission/business processes (Tier 2), or information systems (Tier 3).
A5: Moderate | B5: 21-79 | C5: 5 | D5: Applies to many organizational missions/business functions (Tier 1), mission/business processes (Tier 2), or information systems (Tier 3).
A6: Low | B6: 05 to 20 | C6: 2 | D6: Applies to some organizational missions/business functions (Tier 1), mission/business processes (Tier 2), or information systems (Tier 3).
A7: Very Low | B7: 0-4 | C7: 0 | D7: Applies to few organizational missions/business functions (Tier 1), mission/business processes (Tier 2), or information systems (Tier 3).
A11: TABLE F-6: TEMPLATE – IDENTIFICATION OF PREDISPOSING CONDITIONS
A12: Identifier | B12: Predisposing Condition Source of Information | C12: Pervasiveness of Condition
A13: Organization-defined | B13: Table F-4, Task 1-4 or Organization-defined | C13: Table F-5 or Organization-defined
A14: 1 | B14: Classified National Security Information | C14: High
A15: 2 | B15: Compartments | C15: Moderate
A16: 3 | B16: Controlled Unclassified Information | C16: Moderate
A17: 4 | B17: Personally Unclassified Information | C17: Low
A18: 5 | B18: Special Access Prgroams | C18: High
A19: 6 | B19: Agreement-Determined | C19: Moderate
A20: 7 | B20: Compliance with technical standards | C20: High
A21: 8 | B21: Use of specific products or product lines | C21: Moderate
A22: 9 | B22: Solutions for and/or approaches to user-based collaboration and info sharing | C22: High
A23: 10 | B23: Allocation of specific security functionality to common controls | C23: Moderate
A24: 11 | B24: Networked multiuser | C24: Moderate
A25: 12 | B25: Single-user | C25: Low
... A32: 19 | B32: Clearance/vetting of population | C32: High
A37: TABLE F-2: ASSESSMENT SCALE – VULNERABILITY SEVERITY
A38: Qualitative Values | B38: Semi-Quantitative Values | C38: Values | D38: Description
A39: Very High | B39: 96-100 | C39: 10 | D39: The vulnerability is exposed and exploitable, and its exploitation could result in severe impacts. Relevant security control or other remediation is not implemented and not planned; or no security measure can be identified to remediate the vulnerability
A40: High | B40: 80-95 | C40: 8 | D40: The vulnerability is of high concern, based on the exposure of the vulnerability and ease of exploitation and/or on the severity of impacts that could result from its exploitation. Relevant security control or other remediation is planned but not implemented; compensating controls are in place and at least minimally effective.
A41: Moderate | B41: 21-79 | C41: 5 | D41: The vulnerability is of moderate concern, based on the exposure of the vulnerability and ease of exploitation and/or on the severity of impacts that could result from its exploitation. Relevant security control or other remediation is partially implemented and somewhat effective.
A42: Low | B42: 45797 | C42: 2 | D42: The vulnerability is of minor concern, but effectiveness of remediation could be improved.Relevant security control or other remediation is fully implemented and somewhat effective.
A43: Very Low | B43: 0-4 | C43: 0 | D43: The vulnerability is not of concern. Relevant security control or other remediation is fully implemented, assessed, and effective

Sheet G234
A1: TABLE G-2: ASSESMENT SCALE - ASSESSMENT SCALE – LIKELIHOOD OF THREAT EVENT INITIATION (ADVERSARIAL)
A3: Qualitative Values | B3: Semi- Quantitative Values | C3: Values | D3: Description
A4: Very High | B4: 96 to 100 | C4: 10 | D4: Adversary is almost certain to initiate the threat event.
A5: High | B5: 80 to 95 | C5: 8 | D5: Adversary is highly likely to initiate the threat event.
A6: Moderate | B6: 21 to 79 | C6: 5 | D6: Adversary is somewhat likely to initiate the treat event.
A7: Low | B7: 5 to 20 | C7: 2 | D7: Adversary is unlikely to initiate the threat event.
A8: Very Low | B8: 0 to 4 | C8: 0 | D8: Adversary is highly unlikely to initiate the threat event.
A11: TABLE G-3: ASSESMENT SCALE - ASSESSMENT SCALE – LIKELIHOOD OF THREAT EVENT OCCURENCE (NON-ADVERSARIAL)
A13: Qualitative Values | B13: Semi- Quantitative Values | C13: Values | D13: Description
A14: Very High | B14: 96 to 100 | C14: 10 | D14: Error, accident, or act of nature is almost certain to occur; or occurs more than 100 times a year
A15: High | B15: 80 to 95 | C15: 8 | D15: Error, accident, or act of nature is highly likely to occur; or occurs between 10-100 times a year.
A16: Moderate | B16: 21 to 79 | C16: 5 | D16: Error, accident, or act of nature is somewhat likely to occur; or occurs between 1-10 times a year.
A17: Low | B17: 5 to 20 | C17: 2 | D17: Error, accident, or act of nature is unlikely to occur; or occurs less than once a year, but more than once every 10 years.
A18: Very Low | B18: 0 to 4 | C18: 0 | D18: Error, accident, or act of nature is highly unlikely to occur; or occurs less than once every 10 years.
A21: TABLE G-4: ASSESMENT SCALE - ASSESSMENT SCALE – LIKELIHOOD OF THREAT EVENT RESULTING IN ADVERSE IMPACTS
A23: Qualitative Values | B23: Semi- Quantitative Values | C23: Values | D23: Description
A24: Very High | B24: 96 to 100 | C24: 10 | D24: If the threat event is initiated or occurs, it is almost certain to have adverse impacts.
A25: High | B25: 80 to 95 | C25: 8 | D25: If the threat event is initiated or occurs, it is highly likely to have adverse impacts.
A26: Moderate | B26: 21 to 79 | C26: 5 | D26: If the threat event is initiated or occurs, it is somewhat likely to have adverse impacts.
A27: Low | B27: 5 to 20 | C27: 2 | D27: If the threat event is initiated or occurs, it is unlikely to have adverse impacts.
A28: Very Low | B28: 0 to 4 | C28: 0 | D28: If the threat event is initiated or occurs, it is highly unlikely to have adverse impacts.

Sheet H34
A1: TABLE H-3 ASSESMENT SCALE - IMPACT OF THREAT EVENTS
A2: Qualitative Values | B2: Semi-Quantitative Values | C2: Column1 | D2: Description
A3: Very High | B3: 96-100 | C3: 10 | D3: The threat event could be expected to have multiple severe or catastrophic adverse effects on organizational operations, organizational assets, individuals, other organizations, or the Nation.
A4: High | B4: 21-79 | C4: 8 | D4: The threat event could be expected to have a severe or catastrophic adverse effect on organizational operations, organizational assets, individuals, other organizations, or the Nation. A severe or catastrophic adverse effect means that, for example, the threat event might: (i) cause a severe degradation in or loss of mission capability to an extent and duration that the organization is not able to perform one or more of its primary functions; (ii) result in major damage to organizational assets; (iii) result in major financial loss; or (iv) result in severe or catastrophic harm to individuals involving loss of life or serious life-threatening injuries
A5: Moderate | B5: 21 79 | C5: 5 | D5: The threat event could be expected to have a serious adverse effect on organizational operations, organizational assets, individuals other organizations, or the Nation. A serious adverse effect means that, for example, the threat event might: (i) cause a significant degradation in the mission capability to an extent and duration that the organization is able to perform its primary functions, but the effectiveness of the functions is significantly reduced; (ii) results in significant damage to organizational assets; (iii) result in significant financial loss; or (iv) result in significant harm to individuals that do not involve loss of life or serious life-threatening injuries
A6: Low | B6: 5 20 | C6: 2 | D6: The threat event could be expected to have a limited adverse effect on organizational operations, organizational assets, individuals other organizations, or the Nation. A limited adverse effect means that, for example, the threat event might: (i) cause a degradation in mission capability to an extent and duration that the organization is able to perform its primary functions, but the effectiveness of the functions is noticeably reduced; (ii) result in minor damage to organizational assets; (iii) result in minor financial loss; or (iv) result in minor harm to individuals.
A7: Very Low | B7: 0-4 | C7: 0 | D7: The threat event could be expected to have a negligible adverse effect on organizational operations, organizational assets, individuals other organizations, or the Nation.
A12: TABLE H-4: TEMPLATE – IDENTIFICATION OF ADVERSE IMPACTS
A13: Type of Impact | B13: Impact Affected Asset | C13: Maximum Impact
A14: Table H-2 or Organization-defined | B14: Table H-2 or Organization-defined | C14: Table H-3 or Organization-defined
A15: HARM TO OPERATIONS | B15: Inability to perform current missions/business functions in a sufficiently timely manner | C15: High
A16: HARM TO OPERATIONS | B16: Inability to perform current missions/business functions with sufficient confidence and/or correctness | C16: High
A17: HARM TO OPERATIONS | B17: Inability to perform current missions/business functions within planned resource constraints | C17: High
A18: HARM TO OPERATIONS | B18: Inability, or limited ability, to perform, and restore missions/business functions in the future | C18: High
A19: HARM TO OPERATIONS | B19: Inability, or limited ability, to perform missions/business functions in the future with sufficient confidence and/or correctness | C19: High
A20: HARM TO OPERATIONS | B20: Inability, or limited ability, to perform missions/business functions in the future within planned resource constraints | C20: Moderate
A21: HARM TO OPERATIONS | B21: Harms with applicable laws or regulations | C21: High
A22: HARM TO OPERATIONS | B22: Harms with contractual requirements or other requirements in other binding agreements | C22: Moderate
A23: HARM TO OPERATIONS | B23: Direct financial costs | C23: High
A24: HARM TO OPERATIONS | B24: Damage to trust relationships | C24: Moderate
... A46: HARM TO THE NATION | B46: Damage to current or future ability to achieve national objectives - Harm to national security | C46: Very High
